[2025-07-24T03:18:24.031+0000] {taskinstance.py:1956} INFO - Dependencies all met for dep_context=non-requeueable deps ti=<TaskInstance: TechAndUrbanGrowth.transform_population_data manual__2025-07-24T03:17:57.368913+00:00 [queued]>
[2025-07-24T03:18:24.051+0000] {taskinstance.py:1956} INFO - Dependencies all met for dep_context=requeueable deps ti=<TaskInstance: TechAndUrbanGrowth.transform_population_data manual__2025-07-24T03:17:57.368913+00:00 [queued]>
[2025-07-24T03:18:24.052+0000] {taskinstance.py:2170} INFO - Starting attempt 1 of 2
[2025-07-24T03:18:24.079+0000] {taskinstance.py:2191} INFO - Executing <Task(PythonOperator): transform_population_data> on 2025-07-24 03:17:57.368913+00:00
[2025-07-24T03:18:24.091+0000] {standard_task_runner.py:60} INFO - Started process 2265 to run task
[2025-07-24T03:18:24.096+0000] {standard_task_runner.py:87} INFO - Running: ['***', 'tasks', 'run', 'TechAndUrbanGrowth', 'transform_population_data', 'manual__2025-07-24T03:17:57.368913+00:00', '--job-id', '107', '--raw', '--subdir', 'DAGS_FOLDER/main.py', '--cfg-path', '/tmp/tmprzlp7zf_']
[2025-07-24T03:18:24.102+0000] {standard_task_runner.py:88} INFO - Job 107: Subtask transform_population_data
[2025-07-24T03:18:24.258+0000] {task_command.py:423} INFO - Running <TaskInstance: TechAndUrbanGrowth.transform_population_data manual__2025-07-24T03:17:57.368913+00:00 [running]> on host 4c8899e5e1ad
[2025-07-24T03:18:24.445+0000] {taskinstance.py:2480} INFO - Exporting env vars: AIRFLOW_CTX_DAG_OWNER='***' AIRFLOW_CTX_DAG_ID='TechAndUrbanGrowth' AIRFLOW_CTX_TASK_ID='transform_population_data' AIRFLOW_CTX_EXECUTION_DATE='2025-07-24T03:17:57.368913+00:00' AIRFLOW_CTX_TRY_NUMBER='1' AIRFLOW_CTX_DAG_RUN_ID='manual__2025-07-24T03:17:57.368913+00:00'
[2025-07-24T03:18:24.546+0000] {taskinstance.py:2698} ERROR - Task failed with exception
Traceback (most recent call last):
  File "/home/airflow/.local/lib/python3.8/site-packages/airflow/models/taskinstance.py", line 433, in _execute_task
    result = execute_callable(context=context, **execute_callable_kwargs)
  File "/home/airflow/.local/lib/python3.8/site-packages/airflow/operators/python.py", line 199, in execute
    return_value = self.execute_callable()
  File "/home/airflow/.local/lib/python3.8/site-packages/airflow/operators/python.py", line 216, in execute_callable
    return self.python_callable(*self.op_args, **self.op_kwargs)
  File "/opt/airflow/dags/transform_3.py", line 12, in transform_population_data
    allowed_countries = set(country_codes.split(";"))
AttributeError: 'list' object has no attribute 'split'
[2025-07-24T03:18:24.578+0000] {taskinstance.py:1138} INFO - Marking task as UP_FOR_RETRY. dag_id=TechAndUrbanGrowth, task_id=transform_population_data, execution_date=20250724T031757, start_date=20250724T031824, end_date=20250724T031824
[2025-07-24T03:18:24.637+0000] {standard_task_runner.py:107} ERROR - Failed to execute job 107 for task transform_population_data ('list' object has no attribute 'split'; 2265)
[2025-07-24T03:18:24.713+0000] {local_task_job_runner.py:234} INFO - Task exited with return code 1
[2025-07-24T03:18:24.766+0000] {taskinstance.py:3280} INFO - 0 downstream tasks scheduled from follow-on schedule check
